<?xml version="1.0" ?>
<!-- =================================================================================== -->
<!-- |    This document was autogenerated by xacro from rox.urdf.xacro             | -->
<!-- |    EDITING THIS FILE BY HAND IS NOT RECOMMENDED                                 | -->
<!-- =================================================================================== -->
<robot name="rox">
  <!-- SENSORS -->
  <!-- Sick S300 - Comment/Uncomment if required -->
  <!-- Microscan - Comment/Uncomment if required -->

  <link name="base_link"/>
  <joint name="base_footprint_joint" type="fixed">
    <origin rpy="0 0 0" xyz="0 0 0"/>
    <axis xyz="0 0 -1"/>
    <!-- <limit effort="1000.0" lower="-1e+16" upper="1e+16" velocity="3.5"/> -->
    <joint_properties damping="1" friction="1"/>
    <parent link="base_link"/>
    <child link="base_footprint"/>
  </joint>
  <link name="base_footprint">
    <inertial>
      <mass value="140"/>
      <origin xyz="0 0 0"/>
      <inertia ixx="7.8" ixy="0.0" ixz="0" iyy="7.8" iyz="0.0" izz="7.8"/>
    </inertial>
    <visual>
      <origin rpy="0 0 -1.571" xyz="0.0 0.0 0.123"/>
      <geometry>
        <mesh filename="package://rox_description/meshes/sample.dae" scale="0.1 0.1 0.1"/>
      </geometry>
    </visual>
    <collision>
      <origin rpy="0 0 -1.571" xyz="0. 0. 0.123"/>
      <geometry>
        <mesh filename="package://rox_description/meshes/sample.dae" scale="0.1 0.1 0.1"/>
      </geometry>
    </collision>
  </link>
  <joint name="mpo_700_caster_front_left_joint" type="revolute">
    <origin rpy="0 0 3.14" xyz="0.45 0.21 0.123"/>
    <axis xyz="0 0 1"/>
    <limit effort="1000.0" lower="-1e+16" upper="1e+16" velocity="6.5"/>
    <joint_properties damping="30" friction="110"/>
    <parent link="base_footprint"/>
    <child link="mpo_700_caster_front_left_link"/>
  </joint>
  <link name="mpo_700_caster_front_left_link">
    <inertial>
      <mass value="12.7"/>
      <origin rpy="0 0 0" xyz="0 0 0"/>
      <inertia ixx="0.27258101" ixy="0" ixz="0" iyy="0.27258101" iyz="0" izz="0.27258101"/>
    </inertial>
    <visual>
      <origin rpy="0 0 0" xyz="0 0 0.0"/>
      <geometry>
        <mesh filename="package://rox_description/meshes/argo_caster.dae" scale="0.001 0.001 0.001"/>
      </geometry>
    </visual>
    <collision>
      <origin rpy="0 0 0" xyz="0 0 0.0"/>
      <geometry>
        <mesh filename="package://rox_description/meshes/argo_caster.dae" scale="0.001 0.001 0.001"/>
      </geometry>
    </collision>
  </link>
  <joint name="mpo_700_caster_front_right_joint" type="revolute">
    <origin rpy="0 0 0" xyz="0.45 -0.21 0.123"/>
    <axis xyz="0 0 1"/>
    <limit effort="1000.0" lower="-1e+16" upper="1e+16" velocity="6.5"/>
    <joint_properties damping="30" friction="110"/>
    <parent link="base_footprint"/>
    <child link="mpo_700_caster_front_right_link"/>
  </joint>
  <link name="mpo_700_caster_front_right_link">
    <inertial>
      <mass value="12.7"/>
      <origin rpy="0 0 0" xyz="0 0 0"/>
      <inertia ixx="0.27258101" ixy="0" ixz="0" iyy="0.27258101" iyz="0" izz="0.27258101"/>
    </inertial>
    <visual>
      <origin rpy="0 0 3.14" xyz="0 0 0.0"/>
      <geometry>
        <mesh filename="package://rox_description/meshes/argo_caster.dae" scale="0.001 0.001 0.001"/>
      </geometry>
    </visual>
    <collision>
      <origin rpy="0 0 3.14" xyz="0 0 0.0"/>
      <geometry>
        <mesh filename="package://rox_description/meshes/argo_caster.dae" scale="0.001 0.001 0.001"/>
      </geometry>
    </collision>
  </link>
  <joint name="mpo_700_caster_back_left_joint" type="revolute">
    <origin rpy="0 0 3.14" xyz="-0.45 0.21 0.123"/>
    <axis xyz="0 0 1"/>
    <limit effort="1000.0" lower="-1e+16" upper="1e+16" velocity="6.5"/>
    <joint_properties damping="30" friction="110"/>
    <parent link="base_footprint"/>
    <child link="mpo_700_caster_back_left_link"/>
  </joint>
  <link name="mpo_700_caster_back_left_link">
    <inertial>
      <mass value="12.7"/>
      <origin rpy="0 0 0" xyz="0 0 0"/>
      <inertia ixx="0.27258101" ixy="0" ixz="0" iyy="0.27258101" iyz="0" izz="0.27258101"/>
    </inertial>
    <visual>
      <origin rpy="0 0 0" xyz="0 0 0.0"/>
      <geometry>
        <mesh filename="package://rox_description/meshes/argo_caster.dae" scale="0.001 0.001 0.001"/>
      </geometry>
    </visual>
    <collision>
      <origin rpy="0 0 0" xyz="0 0 0.0"/>
      <geometry>
        <mesh filename="package://rox_description/meshes/argo_caster.dae" scale="0.001 0.001 0.001"/>
      </geometry>
    </collision>
  </link>
  <joint name="mpo_700_caster_back_right_joint" type="revolute">
    <origin rpy="0 0 0" xyz="-0.45 -0.21 0.123"/>
    <axis xyz="0 0 1"/>
    <limit effort="1000.0" lower="-1e+16" upper="1e+16" velocity="6.5"/>
    <joint_properties damping="30" friction="110"/>
    <parent link="base_footprint"/>
    <child link="mpo_700_caster_back_right_link"/>
  </joint>
  <link name="mpo_700_caster_back_right_link">
    <inertial>
      <mass value="12.7"/>
      <origin rpy="0 0 0" xyz="0 0 0"/>
      <inertia ixx="0.27258101" ixy="0" ixz="0" iyy="0.27258101" iyz="0" izz="0.27258101"/>
    </inertial>
    <visual>
      <origin rpy="0 0 3.14" xyz="0 0 0.0"/>
      <geometry>
        <mesh filename="package://rox_description/meshes/argo_caster.dae" scale="0.001 0.001 0.001"/>
      </geometry>
    </visual>
    <collision>
      <origin rpy="0 0 3.14" xyz="0 0 0.0"/>
      <geometry>
        <mesh filename="package://rox_description/meshes/argo_caster.dae" scale="0.001 0.001 0.001"/>
      </geometry>
    </collision>
  </link>
  <joint name="mpo_700_wheel_front_left_joint" type="revolute">
    <origin rpy="0 0 0" xyz="0.0 0.0 -0.07225"/>
    <limit effort="1000.0" lower="-1e+16" upper="1e+16" velocity="20.5"/>
    <axis xyz="0 -1 0"/>
    <joint_properties damping="30" friction="110"/>
    <parent link="mpo_700_caster_front_left_link"/>
    <child link="mpo_700_wheel_front_left_link"/>
  </joint>
  <link name="mpo_700_wheel_front_left_link" type="wheel">
    <inertial>
      <mass value="1.2"/>
      <origin rpy="0 0 0" xyz="0 0 0"/>
      <inertia ixx="0.11042056" ixy="0.0" ixz="0.0" iyy="0.11042056" iyz="0.0" izz="0.11042056"/>
    </inertial>
    <visual>
      <origin rpy="0 0 3.14" xyz="0 0.020 0"/>
      <geometry>
        <mesh filename="package://rox_description/meshes/argo_wheel.dae" scale="0.1 0.1 0.1"/>
      </geometry>
    </visual>
    <collision>
      <origin rpy="0 0 0" xyz="0 0.020 0"/>
      <geometry>
        <sphere radius="0.09"/>
        <!-- <mesh filename="package://rox_description/meshes/argo_wheel.dae" scale="0.001 0.001 0.001"/> -->
      </geometry>
    </collision>
  </link>
  <joint name="mpo_700_wheel_front_right_joint" type="revolute">
    <origin rpy="0 0 3.14" xyz="0.0 0.0 -0.07225"/>
    <limit effort="1000.0" lower="-1e+16" upper="1e+16" velocity="20.5"/>
    <axis xyz="0 -1 0"/>
    <joint_properties damping="30" friction="110"/>
    <parent link="mpo_700_caster_front_right_link"/>
    <child link="mpo_700_wheel_front_right_link"/>
  </joint>
  <link name="mpo_700_wheel_front_right_link" type="wheel">
    <inertial>
      <mass value="1.2"/>
      <origin rpy="0 0 0" xyz="0 0 0"/>
      <inertia ixx="0.11042056" ixy="0.0" ixz="0.0" iyy="0.11042056" iyz="0.0" izz="0.11042056"/>
    </inertial>
    <visual>
      <origin rpy="0 0 3.14" xyz="0 0.020 0"/>
      <geometry>
        <mesh filename="package://rox_description/meshes/argo_wheel.dae" scale="0.1 0.1 0.1"/>
      </geometry>
    </visual>
    <collision>
      <origin rpy="0 0 0" xyz="0 0.020 0"/>
      <geometry>
        <sphere radius="0.09"/>
        <!-- <mesh filename="package://rox_description/meshes/argo_wheel.dae" scale="0.001 0.001 0.001"/> -->
      </geometry>
    </collision>
  </link>
  <joint name="mpo_700_wheel_back_left_joint" type="revolute">
    <origin rpy="0 0 0" xyz="0.0 0.0 -0.07225"/>
    <limit effort="1000.0" lower="-1e+16" upper="1e+16" velocity="20.5"/>
    <axis xyz="0 -1 0"/>
    <joint_properties damping="30" friction="110"/>
    <parent link="mpo_700_caster_back_left_link"/>
    <child link="mpo_700_wheel_back_left_link"/>
  </joint>
  <link name="mpo_700_wheel_back_left_link" type="wheel">
    <inertial>
      <mass value="1.2"/>
      <origin rpy="0 0 0" xyz="0 0 0"/>
      <inertia ixx="0.11042056" ixy="0.0" ixz="0.0" iyy="0.11042056" iyz="0.0" izz="0.11042056"/>
    </inertial>
    <visual>
      <origin rpy="0 0 3.14" xyz="0 0.020 0"/>
      <geometry>
        <mesh filename="package://rox_description/meshes/argo_wheel.dae" scale="0.1 0.1 0.1"/>
      </geometry>
    </visual>
    <collision>
      <origin rpy="0 0 0" xyz="0 0.020 0"/>
      <geometry>
        <sphere radius="0.09"/>
        <!-- <mesh filename="package://rox_description/meshes/argo_wheel.dae" scale="0.001 0.001 0.001"/> -->
      </geometry>
    </collision>
  </link>
  <joint name="mpo_700_wheel_back_right_joint" type="revolute">
    <origin rpy="0 0 3.14" xyz="0.0 0 -0.07225"/>
    <limit effort="1000.0" lower="-1e+16" upper="1e+16" velocity="20.5"/>
    <axis xyz="0 -1 0"/>
    <joint_properties damping="30" friction="110"/>
    <parent link="mpo_700_caster_back_right_link"/>
    <child link="mpo_700_wheel_back_right_link"/>
  </joint>
  <link name="mpo_700_wheel_back_right_link" type="wheel">
    <inertial>
      <mass value="1.2"/>
      <origin rpy="0 0 0" xyz="0 0 0"/>
      <inertia ixx="0.11042056" ixy="0.0" ixz="0.0" iyy="0.11042056" iyz="0.0" izz="0.11042056"/>
    </inertial>
    <visual>
      <origin rpy="0 0 3.14" xyz="0 0.020 0"/>
      <geometry>
        <mesh filename="package://rox_description/meshes/argo_wheel.dae" scale="0.1 0.1 0.1"/>
      </geometry>
    </visual>
    <collision>
      <origin rpy="0 0 0" xyz="0 0.020 0"/>
      <geometry>
        <sphere radius="0.09"/>
        <!-- <mesh filename="package://rox_description/meshes/argo_wheel.dae" scale="0.001 0.001 0.001"/> -->
      </geometry>
    </collision>
  </link>
  <!-- Sensors -->
  <joint name="lidar_1_joint" type="fixed">
    <axis xyz="0 1 0"/>
    <origin rpy="3.14 0 0" xyz="0.60 0.25 0.10"/>
    <parent link="base_link"/>
    <child link="lidar_1_link"/>
  </joint>
  <link name="lidar_1_link" type="laser">
    <inertial>
      <mass value="0.001"/>
      <origin rpy="0 0 0" xyz="0 0 0"/>
      <inertia ixx="0.0001" ixy="0" ixz="0" iyy="0.000001" iyz="0" izz="0.0001"/>
    </inertial>
    <visual>
      <origin rpy="-3.14 0 0" xyz="0 0 -0.0"/>
      <geometry>
        <mesh filename="package://rox_description/meshes/nanoscan_3.dae" scale="0.1 0.1 0.1"/>
      </geometry>
    </visual>
    <collision>
      <origin rpy="-3.14 0 0" xyz="0 0 -0.0"/>
      <geometry>
        <mesh filename="package://rox_description/meshes/nanoscan_3.dae" scale="0.1 0.1 0.1"/>
      </geometry>
    </collision>
  </link>
  <joint name="lidar_2_joint" type="fixed">
    <axis xyz="0 1 0"/>
    <origin rpy="3.14 0 3.14" xyz="-0.60 -0.25 0.10"/>
    <parent link="base_link"/>
    <child link="lidar_2_link"/>
  </joint>
  <link name="lidar_2_link" type="laser">
    <inertial>
      <mass value="0.001"/>
      <origin rpy="-3.14 0 0" xyz="0 0 0.0"/>
      <inertia ixx="0.0001" ixy="0" ixz="0" iyy="0.000001" iyz="0" izz="0.0001"/>
    </inertial>
    <visual>
      <origin rpy="-3.14 0 0" xyz="0 0 -0.0"/>
      <geometry>
        <mesh filename="package://rox_description/meshes/nanoscan_3.dae" scale="0.1 0.1 0.1"/>
      </geometry>
    </visual>
    <collision>
      <origin rpy="-3.14 0 0" xyz="0 0 -0.0"/>
      <geometry>
        <mesh filename="package://rox_description/meshes/nanoscan_3.dae" scale="0.1 0.1 0.1"/>
      </geometry>
    </collision>
  </link>

</robot>
